<robot name ="dog_c">


    <link name="body" >
        <visual>
            <geometry>
                <box size = "0.76 0.28 0.21"/>
            </geometry>
            <origin rpy="0 0 0" xyz= "0 0 0"/>
        <material name="blue">  
            <color rgba="1 0.667 0 1"/>  
        </material>
        </visual>
    </link>


    <link name="base_inertia">
    <inertial>
      <origin rpy="0 0 0" xyz="0 0 0"/>  
      <mass value="10"/>
      <inertia ixx="0.06933" ixy="0" ixz="0" iyy="0.45333" iyz="0" izz="0.48"/>
    </inertial>
    </link>

    <joint name="body_2_base_inertia" type="fixed">
        <origin xyz="0 0 0" rpy="0 0 0" />
        <parent link="body"/>
        <child link="base_inertia"/>
    </joint>

<!--********************************** ALF LEG  **********************************-->
    <link name="ALF_leg1">
        <visual>
            <geometry>
                <cylinder length ="0.1" radius="0.06"/>
            </geometry>
            <origin rpy="0 0 0" xyz= "0 0 0"/>
            <material name="black">  
                <color rgba="0.33725 0.00392 1 1"/>  
            </material> 
        </visual>

        <collision>
            <origin rpy="0 0 0" xyz="0.0 0.0 0.0"/>
            <geometry>
                <cylinder length ="0.1" radius="0.06"/>
            </geometry>
        </collision>

        <inertial>
        <origin rpy="0 0 0" xyz="0.0 0.0 0.0"/>
        <mass value="1.0"/>
        <inertia ixx="0.00173" ixy="0" ixz="0.0" iyy="0.00173" iyz="0.00" izz="0.0018"/>
        </inertial>

    </link>

    <joint name="body_2_ALF_leg1" type="revolute">
        <axis xyz ="0 0 1"/>
        <dynamics damping="0.0" friction="0.0"/> 
        <limit effort="100" velocity="100" lower="-3.1415926" upper="3.1415926" />
        <origin xyz="0.26 0.13 -0.04" rpy="0 1.5708 0" />
        <parent link="body"/>
        <child link="ALF_leg1"/>
    </joint>
    

    <link name="ALF_leg2">
        <visual>
            <geometry>
                <box size="0.07 0.048 0.32"/>
            </geometry>
            <origin rpy="0 0 0" xyz= "0 0 -0.16"/>
            <material name="green">  
                <color rgba="0.33333 0.33333 1 1"/>  
            </material> 
        </visual>

        <collision>
            <origin rpy="0 0 0" xyz="0.0 0.0 -0.16"/>
            <geometry>
                <box size="0.07 0.048 0.32"/>
            </geometry>
        </collision>

        <inertial>
        <origin rpy="0 0 0" xyz="0.0 0.0 -0.16"/>
        <mass value="0.5"/>
        <inertia ixx="0.0043626" ixy="0" ixz="0.0" iyy="0.0044708" iyz="0.00" izz="0.0003001"/>
        </inertial>
    </link>

    <joint name="ALF_leg1_2_ALF_leg2" type="revolute">
        <axis xyz ="0 -1 0"/>
        <dynamics damping="0.0" friction="0.0"/> 
        <limit effort="100" velocity="100" lower="-3.1415926" upper="3.1415926" />
        <origin xyz="0 0 0" rpy="0 -1.5708 0" />
        <parent link="ALF_leg1"/>
        <child link="ALF_leg2"/>
    </joint>


    <link name="ALF_leg3">
        <visual>
            <geometry>
                <box size="0.032 0.034 0.32"/>
            </geometry>
            <origin rpy="0 0 0" xyz= "0 0 -0.16"/>
            <material name="red">  
                <color rgba="0.33333 0.666667 1 1"/>  
            </material> 
        </visual>

        <collision>
            <origin rpy="0 0 0" xyz="0.0 0.0 -0.16"/>
            <geometry>
                <box size="0.032 0.034 0.32"/>
            </geometry>
        </collision>

        <inertial>
        <origin rpy="0 0 0" xyz="0.0 0.0 -0.16"/>
        <mass value="0.1"/>
        <inertia ixx="0.00086296" ixy="0" ixz="0.0" iyy="0.00086186" iyz="0.00" izz="1.8166666666666667e-05"/>
        </inertial>
    </link>

    <joint name="ALF_leg2_2_ALF_leg3" type="revolute">
        <axis xyz ="0 -1 0"/>
        <dynamics damping="0.0" friction="0.0"/> 
        <limit effort="100" velocity="100" lower="-3.1415926" upper="3.1415926" />
        <origin xyz="0 0 -0.32" rpy="0 0 0" />
        <parent link="ALF_leg2"/>
        <child link="ALF_leg3"/>
    </joint>

    <link name="ALF_foot">
        <visual>
            <geometry>
                <sphere radius="0.03"/>
            </geometry>
            <origin rpy="0 0 0" xyz= "0 0 0"/>
            <material name="yellow">  
                <color rgba="0 0 1 1"/>  
            </material> 
        </visual>
        <collision>
            <origin xyz="0 0 0.0"/>
            <geometry>
                <sphere radius="0.03"/>
            </geometry>
        </collision>
    </link>

    <joint name="ALF_leg3_2_foot" type="fixed">
    <origin rpy="0.0 0.0 0.0" xyz="0.0 0.0 -0.32"/>
    <parent link="ALF_leg3"/>
    <child link="ALF_foot"/>
    </joint>


<!--********************************** BRF LEG  **********************************-->
    <link name="BRF_leg1">
        <visual>
            <geometry>
                <cylinder length ="0.1" radius="0.06"/>
            </geometry>
            <origin rpy="0 0 0" xyz= "0 0 0"/>
            <material name="black">  
                <color rgba="0.33725 0.00392 1 1"/>  
            </material> 
        </visual>

        <collision>
            <origin rpy="0 0 0" xyz="0.0 0.0 0.0"/>
            <geometry>
                <cylinder length ="0.1" radius="0.06"/>
            </geometry>
        </collision>

        <inertial>
        <origin rpy="0 0 0" xyz="0.0 0.0 0.0"/>
        <mass value="1.0"/>
        <inertia ixx="0.00173" ixy="0" ixz="0.0" iyy="0.00173" iyz="0.00" izz="0.0018"/>
        </inertial>

    </link>

    <joint name="body_2_BRF_leg1" type="revolute">
        <axis xyz ="0 0 1"/>
        <dynamics damping="0.0" friction="0.0"/> 
        <limit effort="100" velocity="100" lower="-3.1415926" upper="3.1415926" />
        <origin xyz="0.26 -0.13 -0.04" rpy="0 1.5708 0" />
        <parent link="body"/>
        <child link="BRF_leg1"/>
    </joint>
    

    <link name="BRF_leg2">
        <visual>
            <geometry>
                <box size="0.07 0.048 0.32"/>
            </geometry>
            <origin rpy="0 0 0" xyz= "0 0 -0.16"/>
            <material name="green">  
                <color rgba="0.33333 0.33333 1 1"/>  
            </material> 
        </visual>

        <collision>
            <origin rpy="0 0 0" xyz="0.0 0.0 -0.16"/>
            <geometry>
                <box size="0.07 0.048 0.32"/>
            </geometry>
        </collision>

        <inertial>
        <origin rpy="0 0 0" xyz="0.0 0.0 -0.16"/>
        <mass value="0.5"/>
        <inertia ixx="0.0043626" ixy="0" ixz="0.0" iyy="0.0044708" iyz="0.00" izz="0.0003001"/>
        </inertial>
    </link>

    <joint name="BRF_leg1_2_BRF_leg2" type="revolute">
        <axis xyz ="0 -1 0"/>
        <dynamics damping="0.0" friction="0.0"/> 
        <limit effort="100" velocity="100" lower="-3.1415926" upper="3.1415926" />
        <origin xyz="0 0 0" rpy="0 -1.5708 0" />
        <parent link="BRF_leg1"/>
        <child link="BRF_leg2"/>
    </joint>


    <link name="BRF_leg3">
        <visual>
            <geometry>
                <box size="0.032 0.034 0.32"/>
            </geometry>
            <origin rpy="0 0 0" xyz= "0 0 -0.16"/>
            <material name="red">  
                <color rgba="0.33333 0.666667 1 1"/>  
            </material> 
        </visual>

        <collision>
            <origin rpy="0 0 0" xyz="0.0 0.0 -0.16"/>
            <geometry>
                <box size="0.032 0.034 0.32"/>
            </geometry>
        </collision>

        <inertial>
        <origin rpy="0 0 0" xyz="0.0 0.0 -0.16"/>
        <mass value="0.1"/>
        <inertia ixx="0.00086296" ixy="0" ixz="0.0" iyy="0.00086186" iyz="0.00" izz="1.8166666666666667e-05"/>
        </inertial>
    </link>

    <joint name="BRF_leg2_2_BRF_leg3" type="revolute">
        <axis xyz ="0 -1 0"/>
        <dynamics damping="0.0" friction="0.0"/> 
        <limit effort="100" velocity="100" lower="-3.1415926" upper="3.1415926" />
        <origin xyz="0 0 -0.32" rpy="0 0 0" />
        <parent link="BRF_leg2"/>
        <child link="BRF_leg3"/>
    </joint>

    <link name="BRF_foot">
        <visual>
            <geometry>
                <sphere radius="0.03"/>
            </geometry>
            <origin rpy="0 0 0" xyz= "0 0 0"/>
            <material name="yellow">  
                <color rgba="0 0 1 1"/>  
            </material> 
        </visual>
        <collision>
            <origin xyz="0 0 0.0"/>
            <geometry>
                <sphere radius="0.03"/>
            </geometry>
        </collision>
    </link>

    <joint name="BRF_leg3_2_foot" type="fixed">
    <parent link="BRF_leg3"/>
    <child link="BRF_foot"/>
    <origin rpy="0.0 0.0 0.0" xyz="0.0 0.0 -0.32"/>
    </joint>

<!--********************************** CLH LEG  **********************************-->
    <link name="CLH_leg1">
        <visual>
            <geometry>
                <cylinder length ="0.1" radius="0.06"/>
            </geometry>
            <origin rpy="0 0 0" xyz= "0 0 0"/>
            <material name="black">  
                <color rgba="0.33725 0.00392 1 1"/>  
            </material> 
        </visual>

        <collision>
            <origin rpy="0 0 0" xyz="0.0 0.0 0.0"/>
            <geometry>
                <cylinder length ="0.1" radius="0.06"/>
            </geometry>
        </collision>

        <inertial>
        <origin rpy="0 0 0" xyz="0.0 0.0 0.0"/>
        <mass value="1.0"/>
        <inertia ixx="0.00173" ixy="0" ixz="0.0" iyy="0.00173" iyz="0.00" izz="0.0018"/>
        </inertial>

    </link>

    <joint name="body_2_CLH_leg1" type="revolute">
        <axis xyz ="0 0 1"/>
        <dynamics damping="0.0" friction="0.0"/> 
        <limit effort="100" velocity="100" lower="-3.1415926" upper="3.1415926" />
        <origin xyz="-0.26 0.13 -0.04" rpy="0 1.5708 0" />
        <parent link="body"/>
        <child link="CLH_leg1"/>
    </joint>
    

    <link name="CLH_leg2">
        <visual>
            <geometry>
                <box size="0.07 0.048 0.32"/>
            </geometry>
            <origin rpy="0 0 0" xyz= "0 0 -0.16"/>
            <material name="green">  
                <color rgba="0.33333 0.33333 1 1"/>  
            </material> 
        </visual>

        <collision>
            <origin rpy="0 0 0" xyz="0.0 0.0 -0.16"/>
            <geometry>
                <box size="0.07 0.048 0.32"/>
            </geometry>
        </collision>

        <inertial>
        <origin rpy="0 0 0" xyz="0.0 0.0 -0.16"/>
        <mass value="0.5"/>
        <inertia ixx="0.0043626" ixy="0" ixz="0.0" iyy="0.0044708" iyz="0.00" izz="0.0003001"/>
        </inertial>
    </link>

    <joint name="CLH_leg1_2_CLH_leg2" type="revolute">
        <axis xyz ="0 -1 0"/>
        <dynamics damping="0.0" friction="0.0"/> 
        <limit effort="100" velocity="100" lower="-3.1415926" upper="3.1415926" />
        <origin xyz="0 0 0" rpy="0 -1.5708 0" />
        <parent link="CLH_leg1"/>
        <child link="CLH_leg2"/>
    </joint>


    <link name="CLH_leg3">
        <visual>
            <geometry>
                <box size="0.032 0.034 0.32"/>
            </geometry>
            <origin rpy="0 0 0" xyz= "0 0 -0.16"/>
            <material name="red">  
                <color rgba="0.33333 0.666667 1 1"/>  
            </material> 
        </visual>

        <collision>
            <origin rpy="0 0 0" xyz="0.0 0.0 -0.16"/>
            <geometry>
                <box size="0.032 0.034 0.32"/>
            </geometry>
        </collision>

        <inertial>
        <origin rpy="0 0 0" xyz="0.0 0.0 -0.16"/>
        <mass value="0.1"/>
        <inertia ixx="0.00086296" ixy="0" ixz="0.0" iyy="0.00086186" iyz="0.00" izz="1.8166666666666667e-05"/>
        </inertial>
    </link>

    <joint name="CLH_leg2_2_CLH_leg3" type="revolute">
        <axis xyz ="0 -1 0"/>
        <dynamics damping="0.0" friction="0.0"/> 
        <limit effort="100" velocity="100" lower="-3.1415926" upper="3.1415926" />
        <origin xyz="0 0 -0.32" rpy="0 0 0" />
        <parent link="CLH_leg2"/>
        <child link="CLH_leg3"/>
    </joint>

    <link name="CLH_foot">
        <visual>
            <geometry>
                <sphere radius="0.03"/>
            </geometry>
            <origin rpy="0 0 0" xyz= "0 0 0"/>
            <material name="yellow">  
                <color rgba="0 0 1 1"/>  
            </material> 
        </visual>
        <collision>
            <origin xyz="0 0 0.0"/>
            <geometry>
                <sphere radius="0.03"/>
            </geometry>
        </collision>
    </link>

    <joint name="CLH_leg3_2_foot" type="fixed">
    <parent link="CLH_leg3"/>
    <child link="CLH_foot"/>
    <origin rpy="0.0 0.0 0.0" xyz="0.0 0.0 -0.32"/>
    </joint>

<!--********************************** DRH LEG  **********************************-->
    <link name="DRH_leg1">
        <visual>
            <geometry>
                <cylinder length ="0.1" radius="0.06"/>
            </geometry>
            <origin rpy="0 0 0" xyz= "0 0 0"/>
            <material name="black">  
                <color rgba="0.33725 0.00392 1 1"/>  
            </material> 
        </visual>

        <collision>
            <origin rpy="0 0 0" xyz="0.0 0.0 0.0"/>
            <geometry>
                <cylinder length ="0.1" radius="0.06"/>
            </geometry>
        </collision>

        <inertial>
        <origin rpy="0 0 0" xyz="0.0 0.0 0.0"/>
        <mass value="1.0"/>
        <inertia ixx="0.00173" ixy="0" ixz="0.0" iyy="0.00173" iyz="0.00" izz="0.0018"/>
        </inertial>

    </link>

    <joint name="body_2_DRH_leg1" type="revolute">
        <axis xyz ="0 0 1"/>
        <dynamics damping="0.0" friction="0.0"/> 
        <limit effort="100" velocity="100" lower="-3.1415926" upper="3.1415926" />
        <origin xyz=" -0.26 -0.13 -0.04" rpy="0 1.5708 0" />
        <parent link="body"/>
        <child link="DRH_leg1"/>
    </joint>
    

    <link name="DRH_leg2">
        <visual>
            <geometry>
                <box size="0.07 0.048 0.32"/>
            </geometry>
            <origin rpy="0 0 0" xyz= "0 0 -0.16"/>
            <material name="green">  
                <color rgba="0.33333 0.33333 1 1"/>  
            </material> 
        </visual>

        <collision>
            <origin rpy="0 0 0" xyz="0.0 0.0 -0.16"/>
            <geometry>
                <box size="0.07 0.048 0.32"/>
            </geometry>
        </collision>

        <inertial>
        <origin rpy="0 0 0" xyz="0.0 0.0 -0.16"/>
        <mass value="0.5"/>
        <inertia ixx="0.0043626" ixy="0" ixz="0.0" iyy="0.0044708" iyz="0.00" izz="0.0003001"/>
        </inertial>
    </link>

    <joint name="DRH_leg1_2_DRH_leg2" type="revolute">
        <axis xyz ="0 -1 0"/>
        <dynamics damping="0.0" friction="0.0"/> 
        <limit effort="100" velocity="100" lower="-3.1415926" upper="3.1415926" />
        <origin xyz="0 0 0" rpy="0 -1.5708 0" />
        <parent link="DRH_leg1"/>
        <child link="DRH_leg2"/>
    </joint>


    <link name="DRH_leg3">
        <visual>
            <geometry>
                <box size="0.032 0.034 0.32"/>
            </geometry>
            <origin rpy="0 0 0" xyz= "0 0 -0.16"/>
            <material name="red">  
                <color rgba="0.33333 0.666667 1 1"/>  
            </material> 
        </visual>

        <collision>
            <origin rpy="0 0 0" xyz="0.0 0.0 -0.16"/>
            <geometry>
                <box size="0.032 0.034 0.32"/>
            </geometry>
        </collision>

        <inertial>
        <origin rpy="0 0 0" xyz="0.0 0.0 -0.16"/>
        <mass value="0.1"/>
        <inertia ixx="0.00086296" ixy="0" ixz="0.0" iyy="0.00086186" iyz="0.00" izz="1.8166666666666667e-05"/>
        </inertial>
    </link>

    <joint name="DRH_leg2_2_DRH_leg3" type="revolute">
        <axis xyz ="0 -1 0"/>
        <dynamics damping="0.0" friction="0.0"/> 
        <limit effort="100" velocity="100" lower="-3.1415926" upper="3.1415926" />
        <origin xyz="0 0 -0.32" rpy="0 0 0" />
        <parent link="DRH_leg2"/>
        <child link="DRH_leg3"/>
    </joint>

    <link name="DRH_foot">
        <visual>
            <geometry>
                <sphere radius="0.03"/>
            </geometry>
            <origin rpy="0 0 0" xyz= "0 0 0"/>
            <material name="yellow">  
                <color rgba="0 0 1 1"/>  
            </material> 
        </visual>
        <collision>
            <origin xyz="0 0 0.0"/>
            <geometry>
                <sphere radius="0.03"/>
            </geometry>
        </collision>
    </link>

    <joint name="DRH_leg3_2_foot" type="fixed">
    <parent link="DRH_leg3"/>
    <child link="DRH_foot"/>
    <origin rpy="0.0 0.0 0.0" xyz="0.0 0.0 -0.32"/>
    </joint>
</robot>